Workbook

Sheet Students
A1: student_id | B1: profile_id | C1: register_number | D1: full_name | E1: email | F1: department_code | G1: department_name | H1: degree_type | I1: program | J1: academic_year | K1: admission_year | L1: is_active | M1: credit_points
A2: bfff0937-1f72-5cc8-9b67-2154ff97a73e | B2: 1059f8a9-b931-5ee8-8470-9ee8e23305db | C2: NEC26CS001 | D2: Janani Subramanian | E2: janani.subramanian@nec.edu.in | F2: CSE | G2: Computer Science and Engineering | H2: UG | I2: B.E. | J2: 1 | K2: 2026 | L2: =TRUE() -> TRUE | M2: 13
A3: 0b9ef2c0-7634-5012-b5b6-a66a357de25f | B3: 21941459-f7dc-5aec-88ab-7d50bd391efc | C3: NEC26CS002 | D3: Pooja Balaji | E3: pooja.balaji@nec.edu.in | F3: CSE | G3: Computer Science and Engineering | H3: UG | I3: B.E. | J3: 1 | K3: 2026 | L3: =TRUE() -> TRUE | M3: 18
A4: e4f73750-6073-5662-92ab-c37d712b25fe | B4: 8ba6e064-e997-5f9c-8ee9-c24a4c752754 | C4: NEC26CS003 | D4: Selvam Krishnan | E4: selvam.krishnan@nec.edu.in | F4: CSE | G4: Computer Science and Engineering | H4: UG | I4: B.E. | J4: 1 | K4: 2026 | L4: =TRUE() -> TRUE | M4: 1
A5: 7df21a5e-03ac-500a-a78c-d904f818832d | B5: 520e74ce-b2cd-596d-a7ae-89a1bbb520c1 | C5: NEC25CS001 | D5: Deepak Muthusamy | E5: deepak.muthusamy@nec.edu.in | F5: CSE | G5: Computer Science and Engineering | H5: UG | I5: B.E. | J5: 2 | K5: 2025 | L5: =TRUE() -> TRUE | M5: 41
A6: 53fb18ed-fac0-51e7-8ad9-7baac2b45aa1 | B6: baeb2fa4-43d5-5d52-b0b5-e03a09daa5cb | C6: NEC25CS002 | D6: Anjali Annamalai | E6: anjali.annamalai@nec.edu.in | F6: CSE | G6: Computer Science and Engineering | H6: UG | I6: B.E. | J6: 2 | K6: 2025 | L6: =TRUE() -> TRUE | M6: 42
A7: a420ed9f-07ae-5dee-b107-60a095f6f8ac | B7: de9cbf4f-1a21-5679-8cb6-787990671b7a | C7: NEC25CS003 | D7: Arun Thangaraj | E7: arun.thangaraj@nec.edu.in | F7: CSE | G7: Computer Science and Engineering | H7: UG | I7: B.E. | J7: 2 | K7: 2025 | L7: =TRUE() -> TRUE | M7: 43
A8: 5d0a25cd-c9af-53d4-8a43-4474e0ffedac | B8: 9d67af51-91af-5e4e-88e0-306573349acb | C8: NEC24CS001 | D8: Abinaya Sundaram | E8: abinaya.sundaram@nec.edu.in | F8: CSE | G8: Computer Science and Engineering | H8: UG | I8: B.E. | J8: 3 | K8: 2024 | L8: =TRUE() -> TRUE | M8: 58
A9: 01026d60-06b3-5d21-8b3a-f86ee4ad85f4 | B9: 0b33a7d7-f80d-55d3-81bf-2af24474a9c9 | C9: NEC24CS002 | D9: Sathish Muthusamy | E9: sathish.muthusamy@nec.edu.in | F9: CSE | G9: Computer Science and Engineering | H9: UG | I9: B.E. | J9: 3 | K9: 2024 | L9: =TRUE() -> TRUE | M9: 26
A10: 26aaf967-0ec3-5cc6-b958-231da201e75a | B10: 89d2bd09-7c9e-5270-9cf3-ce8832b70330 | C10: NEC24CS003 | D10: Yuvaraj Govindan | E10: yuvaraj.govindan@nec.edu.in | F10: CSE | G10: Computer Science and Engineering | H10: UG | I10: B.E. | J10: 3 | K10: 2024 | L10: =TRUE() -> TRUE | M10: 31
A11: 564e884c-7616-54e3-925e-8d16471bae0e | B11: 5e9e4f17-cd4a-5748-9e5b-0d9ae0374895 | C11: NEC23CS001 | D11: Rahul Venkatesh | E11: rahul.venkatesh@nec.edu.in | F11: CSE | G11: Computer Science and Engineering | H11: UG | I11: B.E. | J11: 4 | K11: 2023 | L11: =TRUE() -> TRUE | M11: 94
A12: 02a28bbe-b82d-5c61-ae2f-c4cb3f63b904 | B12: 5af41301-def1-5d91-90af-c6bce452cd86 | C12: NEC23CS002 | D12: Vignesh Periyasamy | E12: vignesh.periyasamy@nec.edu.in | F12: CSE | G12: Computer Science and Engineering | H12: UG | I12: B.E. | J12: 4 | K12: 2023 | L12: =TRUE() -> TRUE | M12: 54
A13: 84804b90-08e8-5cf3-b6cd-f0e0a6c0694f | B13: 8b33586c-4f5d-557e-99e8-99d4ad9df3c2 | C13: NEC23CS003 | D13: Pranav Thangaraj | E13: pranav.thangaraj@nec.edu.in | F13: CSE | G13: Computer Science and Engineering | H13: UG | I13: B.E. | J13: 4 | K13: 2023 | L13: =TRUE() -> TRUE | M13: 79
... A18: e2286a33-d944-552d-af00-429a8d7fa53f | B18: b920ca61-8c88-5aec-a85d-f0c37fcf8a1a | C18: NEC24IT001 | D18: Mythili Chandran | E18: mythili.chandran@nec.edu.in | F18: IT | G18: Information Technology | H18: UG | I18: B.Tech | J18: 3 | K18: 2024 | L18: =TRUE() -> TRUE | M18: 32
A19: 5af22c77-ee82-562f-9792-74847a52cf6d | B19: 2e11a7da-fefe-5264-9522-1b7c07cb3f5a | C19: NEC24IT002 | D19: Keerthana Venkatesh | E19: keerthana.venkatesh@nec.edu.in | F19: IT | G19: Information Technology | H19: UG | I19: B.Tech | J19: 3 | K19: 2024 | L19: =FALSE() -> FALSE | M19: 60
A20: af0e3432-9375-5052-9a08-80eafc1c2b13 | B20: 7ab361ba-797f-5f8f-be3b-7594ce545328 | C20: NEC23IT001 | D20: Naveen Sekar | E20: naveen.sekar@nec.edu.in | F20: IT | G20: Information Technology | H20: UG | I20: B.Tech | J20: 4 | K20: 2023 | L20: =TRUE() -> TRUE | M20: 84
A21: 9c4e722a-6bed-5aad-9f6f-bfb66fdd0ad9 | B21: 5baf24f6-0c39-5f4f-be04-8a836129bb95 | C21: NEC23IT002 | D21: Manoj Sundaram | E21: manoj.sundaram@nec.edu.in | F21: IT | G21: Information Technology | H21: UG | I21: B.Tech | J21: 4 | K21: 2023 | L21: =TRUE() -> TRUE | M21: 82
A22: fdf7b5c1-b0d6-5654-b63c-800c4d42c4dc | B22: d20af355-ba06-59f0-ab9f-88bb4c413795 | C22: NEC26EC001 | D22: Harini Natarajan | E22: harini.natarajan@nec.edu.in | F22: ECE | G22: Electronics and Communication Engineering | H22: UG | I22: B.E. | J22: 1 | K22: 2026 | L22: =TRUE() -> TRUE | M22: 17
A23: 3c258a15-9c34-5aad-8a0a-898673477f3f | B23: f3094b46-fe94-57ab-b24c-fc9bce4332ff | C23: NEC26EC002 | D23: Nandhini Palanisamy | E23: nandhini.palanisamy@nec.edu.in | F23: ECE | G23: Electronics and Communication Engineering | H23: UG | I23: B.E. | J23: 1 | K23: 2026 | L23: =TRUE() -> TRUE | M23: 9
A24: 547cb137-9a86-58f8-ae80-64ec99c12c21 | B24: 3de7a148-9e7a-542e-a68d-b0c14201f410 | C24: NEC25EC001 | D24: Akash Sekar | E24: akash.sekar@nec.edu.in | F24: ECE | G24: Electronics and Communication Engineering | H24: UG | I24: B.E. | J24: 2 | K24: 2025 | L24: =TRUE() -> TRUE | M24: 42
A25: 61bcc309-2354-50fc-8c62-ae2ee4731b2a | B25: 8b981578-4373-5f8a-a46a-2adb255a6a82 | C25: NEC25EC002 | D25: Ramya Venkatesh | E25: ramya.venkatesh@nec.edu.in | F25: ECE | G25: Electronics and Communication Engineering | H25: UG | I25: B.E. | J25: 2 | K25: 2025 | L25: =TRUE() -> TRUE | M25: 10
A26: 30761d11-c772-5ff5-a0aa-9dae123b6564 | B26: 9137ae2a-f9ee-5c91-b7fd-5aaf282f15ad | C26: NEC24EC001 | D26: Tharun Thangaraj | E26: tharun.thangaraj@nec.edu.in | F26: ECE | G26: Electronics and Communication Engineering | H26: UG | I26: B.E. | J26: 3 | K26: 2024 | L26: =TRUE() -> TRUE | M26: 55
A27: 8a954d2d-4654-5141-8200-710af5c3d83a | B27: a5c22cf5-4416-515b-bd49-17f19f75203d | C27: NEC24EC002 | D27: Nithya Rajan | E27: nithya.rajan@nec.edu.in | F27: ECE | G27: Electronics and Communication Engineering | H27: UG | I27: B.E. | J27: 3 | K27: 2024 | L27: =TRUE() -> TRUE | M27: 34
A28: 09d0c1ca-bf6e-59ee-863c-3357be2aa69c | B28: 8cc7aa55-e93b-5bea-92ca-85c6a03292e5 | C28: NEC23EC001 | D28: Karthik Sundaram | E28: karthik.sundaram@nec.edu.in | F28: ECE | G28: Electronics and Communication Engineering | H28: UG | I28: B.E. | J28: 4 | K28: 2023 | L28: =TRUE() -> TRUE | M28: 67
A29: ed85fd6d-0361-58fe-b357-1fde8bc4b94c | B29: 02ce55e6-5cfc-5de3-a4c8-b9cf9c030394 | C29: NEC23EC002 | D29: Dinesh Sekar | E29: dinesh.sekar@nec.edu.in | F29: ECE | G29: Electronics and Communication Engineering | H29: UG | I29: B.E. | J29: 4 | K29: 2023 | L29: =TRUE() -> TRUE | M29: 96
A30: 803a7296-246a-5a84-9416-01d323f9f178 | B30: 63e20a6a-924c-55ef-9047-cd9eb764cadd | C30: NEC26EE001 | D30: Harish Karthikeyan | E30: harish.karthikeyan@nec.edu.in | F30: EEE | G30: Electrical and Electronics Engineering | H30: UG | I30: B.E. | J30: 1 | K30: 2026 | L30: =TRUE() -> TRUE | M30: 14
A31: 48951a87-12aa-5b23-9440-3d35e77dc610 | B31: bf725324-c608-520b-a7a0-a0c057f4761e | C31: NEC26EE002 | D31: Vimal Annamalai | E31: vimal.annamalai@nec.edu.in | F31: EEE | G31: Electrical and Electronics Engineering | H31: UG | I31: B.E. | J31: 1 | K31: 2026 | L31: =TRUE() -> TRUE | M31: 14
... A45: 59c0e9dc-250a-5b31-bc93-2657ba421fd0 | B45: 56f74ec6-a5cb-5ce3-9df2-356b3b2e1bb1 | C45: NEC23CE001 | D45: Priya Murugan | E45: priya.murugan@nec.edu.in | F45: CIVIL | G45: Civil Engineering | H45: UG | I45: B.E. | J45: 4 | K45: 2023 | L45: =TRUE() -> TRUE | M45: 81
A46: 043d330d-be8e-5100-83e5-f9a6b5d7f3bb | B46: c0b931ce-04e7-5ee8-9995-62976fc548ab | C46: NEC26AD001 | D46: Suriya Venkatesh | E46: suriya.venkatesh@nec.edu.in | F46: AIDS | G46: Artificial Intelligence and Data Science | H46: UG | I46: B.Tech | J46: 1 | K46: 2026 | L46: =FALSE() -> FALSE | M46: 15
A47: f584e5a5-40ca-5111-a2ba-c8864051bd07 | B47: 19a78f29-1f29-5da1-9d5b-cf7a7bd87b85 | C47: NEC26AD002 | D47: Subash Arumugam | E47: subash.arumugam@nec.edu.in | F47: AIDS | G47: Artificial Intelligence and Data Science | H47: UG | I47: B.Tech | J47: 1 | K47: 2026 | L47: =TRUE() -> TRUE | M47: 0
A48: 95e9ad05-3d9b-5043-8ed4-5f8c0e1ed4ea | B48: 8b2dbcc5-8b23-59dc-9276-6cb5a42d4fe7 | C48: NEC25AD001 | D48: Sanjay Raman | E48: sanjay.raman@nec.edu.in | F48: AIDS | G48: Artificial Intelligence and Data Science | H48: UG | I48: B.Tech | J48: 2 | K48: 2025 | L48: =TRUE() -> TRUE | M48: 16
A49: 36e91b1b-24c0-5716-b447-5b33e0f65054 | B49: 338d940f-3222-52d8-8b0f-c9a1579ce8ff | C49: NEC25AD002 | D49: Pavithra Murugan | E49: pavithra.murugan@nec.edu.in | F49: AIDS | G49: Artificial Intelligence and Data Science | H49: UG | I49: B.Tech | J49: 2 | K49: 2025 | L49: =TRUE() -> TRUE | M49: 10
A50: c60a4f34-f414-5855-a7db-a3a258ce1e03 | B50: 4c2de6e5-6c23-53c8-9e6b-3b5300c6dd50 | C50: NEC24AD001 | D50: Monisha Palanisamy | E50: monisha.palanisamy@nec.edu.in | F50: AIDS | G50: Artificial Intelligence and Data Science | H50: UG | I50: B.Tech | J50: 3 | K50: 2024 | L50: =TRUE() -> TRUE | M50: 72
A51: 742c3116-6c80-53e1-a9af-ad51c50d09ec | B51: f0baa55e-3a2a-5669-a688-cac433d1b7e8 | C51: NEC23AD001 | D51: Kowsalya Balaji | E51: kowsalya.balaji@nec.edu.in | F51: AIDS | G51: Artificial Intelligence and Data Science | H51: UG | I51: B.Tech | J51: 4 | K51: 2023 | L51: =TRUE() -> TRUE | M51: 49
A52: 9b0846e6-8b10-5bb3-a741-8ebe5154c5fc | B52: 597031ec-1d00-598b-8d03-5a620d929af7 | C52: NEC26PS001 | D52: Sowmiya Arumugam | E52: sowmiya.arumugam@nec.edu.in | F52: ME-CSE | G52: M.E. Computer Science and Engineering | H52: PG | I52: M.E. | J52: 1 | K52: 2026 | L52: =TRUE() -> TRUE | M52: 18
A53: a253b686-85ef-526e-b356-464a74577f29 | B53: ca833645-6e0e-5cc2-8b13-93d8b5b280a0 | C53: NEC26PS002 | D53: Swetha Karthikeyan | E53: swetha.karthikeyan@nec.edu.in | F53: ME-CSE | G53: M.E. Computer Science and Engineering | H53: PG | I53: M.E. | J53: 1 | K53: 2026 | L53: =TRUE() -> TRUE | M53: 6
A54: 2d1fae84-fefd-5be5-b372-aed4efe8cbf1 | B54: 34a0d64a-b229-531b-a0d8-516f277a5e4e | C54: NEC25PS001 | D54: Thamizh Ramasamy | E54: thamizh.ramasamy@nec.edu.in | F54: ME-CSE | G54: M.E. Computer Science and Engineering | H54: PG | I54: M.E. | J54: 2 | K54: 2025 | L54: =TRUE() -> TRUE | M54: 15
A55: 100a466f-6c31-5ae3-b132-18137013d3a1 | B55: c65e3096-f933-582a-988d-e2f45e0ab10a | C55: NEC26MB001 | D55: Jeeva Chandran | E55: jeeva.chandran@nec.edu.in | F55: MBA | G55: Master of Business Administration | H55: PG | I55: MBA | J55: 1 | K55: 2026 | L55: =TRUE() -> TRUE | M55: 3
A56: 4f991c61-af61-5e5c-8814-ca888c10cf58 | B56: 76e4cf2d-a2c1-5c4c-b726-b860517d967c | C56: NEC26MB002 | D56: Vishnu Ramasamy | E56: vishnu.ramasamy@nec.edu.in | F56: MBA | G56: Master of Business Administration | H56: PG | I56: MBA | J56: 1 | K56: 2026 | L56: =TRUE() -> TRUE | M56: 8
A57: c67be234-1b84-5473-9f79-2c54ac41c165 | B57: 7debde5b-92eb-54d2-b488-5a2bb2aed3cb | C57: NEC25MB001 | D57: Bharathi Karthikeyan | E57: bharathi.karthikeyan@nec.edu.in | F57: MBA | G57: Master of Business Administration | H57: PG | I57: MBA | J57: 2 | K57: 2025 | L57: =TRUE() -> TRUE | M57: 12
...

Sheet Departments
A1: department_code | B1: department_name | C1: degree_type | D1: program | E1: reg_code | F1: is_active | G1: student_count | H1: avg_credit_points
A2: CSE | B2: Computer Science and Engineering | C2: UG | D2: B.E. | E2: CS | F2: =TRUE() -> TRUE | G2: =COUNTIF(Students!$F$2:$F$61,A2) -> 12 | H2: =IFERROR(AVERAGEIF(Students!$F$2:$F$61,A2,Students!$M$2:$M$61),0) -> 41.666667
A3: IT | B3: Information Technology | C3: UG | D3: B.Tech | E3: IT | F3: =TRUE() -> TRUE | G3: =COUNTIF(Students!$F$2:$F$61,A3) -> 8 | H3: =IFERROR(AVERAGEIF(Students!$F$2:$F$61,A3,Students!$M$2:$M$61),0) -> 46.5
A4: ECE | B4: Electronics and Communication Engineering | C4: UG | D4: B.E. | E4: EC | F4: =TRUE() -> TRUE | G4: =COUNTIF(Students!$F$2:$F$61,A4) -> 8 | H4: =IFERROR(AVERAGEIF(Students!$F$2:$F$61,A4,Students!$M$2:$M$61),0) -> 41.25
A5: EEE | B5: Electrical and Electronics Engineering | C5: UG | D5: B.E. | E5: EE | F5: =TRUE() -> TRUE | G5: =COUNTIF(Students!$F$2:$F$61,A5) -> 6 | H5: =IFERROR(AVERAGEIF(Students!$F$2:$F$61,A5,Students!$M$2:$M$61),0) -> 38.5
A6: MECH | B6: Mechanical Engineering | C6: UG | D6: B.E. | E6: ME | F6: =TRUE() -> TRUE | G6: =COUNTIF(Students!$F$2:$F$61,A6) -> 6 | H6: =IFERROR(AVERAGEIF(Students!$F$2:$F$61,A6,Students!$M$2:$M$61),0) -> 38
A7: CIVIL | B7: Civil Engineering | C7: UG | D7: B.E. | E7: CE | F7: =TRUE() -> TRUE | G7: =COUNTIF(Students!$F$2:$F$61,A7) -> 4 | H7: =IFERROR(AVERAGEIF(Students!$F$2:$F$61,A7,Students!$M$2:$M$61),0) -> 46.75
A8: AIDS | B8: Artificial Intelligence and Data Science | C8: UG | D8: B.Tech | E8: AD | F8: =TRUE() -> TRUE | G8: =COUNTIF(Students!$F$2:$F$61,A8) -> 6 | H8: =IFERROR(AVERAGEIF(Students!$F$2:$F$61,A8,Students!$M$2:$M$61),0) -> 27
A9: ME-CSE | B9: M.E. Computer Science and Engineering | C9: PG | D9: M.E. | E9: PS | F9: =TRUE() -> TRUE | G9: =COUNTIF(Students!$F$2:$F$61,A9) -> 3 | H9: =IFERROR(AVERAGEIF(Students!$F$2:$F$61,A9,Students!$M$2:$M$61),0) -> 13
A10: MBA | B10: Master of Business Administration | C10: PG | D10: MBA | E10: MB | F10: =TRUE() -> TRUE | G10: =COUNTIF(Students!$F$2:$F$61,A10) -> 4 | H10: =IFERROR(AVERAGEIF(Students!$F$2:$F$61,A10,Students!$M$2:$M$61),0) -> 13.75
A11: MCA | B11: Master of Computer Applications | C11: PG | D11: MCA | E11: MA | F11: =TRUE() -> TRUE | G11: =COUNTIF(Students!$F$2:$F$61,A11) -> 3 | H11: =IFERROR(AVERAGEIF(Students!$F$2:$F$61,A11,Students!$M$2:$M$61),0) -> 15
A12: Total | G12: =SUM(G2:G11) -> 60 | H12: =AVERAGE(Students!$M$2:$M$61) -> 35.816667

Sheet Notes
A1: NEC-SCS sample student data (60 records)
A3: All names, emails and register numbers are fictional and for testing only.
A4: Columns follow the students / profiles / departments tables in the NEC-SCS schema (student_id, profile_id, register_number, academic_year, etc.).
A5: Register number format: NEC + 2-digit admission year + 2-letter department code + 3-digit sequence (e.g. NEC24CS001). Department codes are on the Departments sheet.
A6: Assumption: current academic year is 2026-27, so year 1 = admitted 2026, year 2 = 2025, year 3 = 2024, year 4 = 2023. UG has years 1-4, PG has years 1-2.
A7: Assumption: emails use @nec.edu.in, one of the institutional domain aliases listed in the project README.
A8: student_id and profile_id are deterministic UUIDs generated for this sample; replace them with real Supabase IDs on import.
A9: credit_points are random sample values scaled by academic year; they are not derived from certificates.
A10: Two students have is_active = FALSE so the inactive-account login rule can be tested.
A11: No passwords are included. Set them through your auth flow or seed script.
A12: Departments!G and H are formulas (COUNTIF / AVERAGEIF on the Students sheet) and update if you edit student rows within rows 2-61.
